Workbook

Sheet Ringkasan
A1: Ringkasan verifikasi dan uji sensitivitas
A2: Data: glm_rag_v2.csv (LLM + RAG) dan glm_llm.csv (LLM saja), 40 soal, penilai GLM-4.7-flash. Kategori usulan berasal dari pemeriksaan jawaban terhadap rujukan dan perlu dikonfirmasi peneliti di sheet Verifikasi nol.
A4: Jumlah skor FC = 0 menurut kategori usulan
A5: Mode | B5: Nol wajar | C5: Nol diragukan | D5: Total nol | E5: Sudah dikonfirmasi Setuju
A6: LLM saja | B6: =COUNTIFS('Verifikasi nol'!$C$5:$C$25,A6,'Verifikasi nol'!$H$5:$H$25,"Nol wajar") -> 6 | C6: =COUNTIFS('Verifikasi nol'!$C$5:$C$25,A6,'Verifikasi nol'!$H$5:$H$25,"Nol diragukan") -> 11 | D6: =B6+C6 -> 17 | E6: =COUNTIFS('Verifikasi nol'!$C$5:$C$25,A6,'Verifikasi nol'!$J$5:$J$25,"Setuju") -> 0
A7: LLM + RAG | B7: =COUNTIFS('Verifikasi nol'!$C$5:$C$25,A7,'Verifikasi nol'!$H$5:$H$25,"Nol wajar") -> 1 | C7: =COUNTIFS('Verifikasi nol'!$C$5:$C$25,A7,'Verifikasi nol'!$H$5:$H$25,"Nol diragukan") -> 3 | D7: =B7+C7 -> 4 | E7: =COUNTIFS('Verifikasi nol'!$C$5:$C$25,A7,'Verifikasi nol'!$J$5:$J$25,"Setuju") -> 0
A8: Total | B8: =SUM(B6:B7) -> 7 | C8: =SUM(C6:C7) -> 14 | D8: =SUM(D6:D7) -> 21 | E8: =SUM(E6:E7) -> 0
A10: Soal yang dikeluarkan pada uji sensitivitas (kategori Nol diragukan di salah satu mode): 1, 5, 6, 7, 11, 13, 21, 28, 31, 34, 37, 40
A12: Uji Wilcoxon berpasangan: LLM + RAG vs LLM saja
A13: Skenario | B13: Metrik | C13: n | D13: Rata-rata RAG | E13: Rata-rata LLM saja | F13: Nilai p | G13: Ukuran efek r | H13: RAG lebih tinggi/lebih rendah/sama
A14: Semua soal | B14: Factual correctness | C14: 40 | D14: 0.465 | E14: 0.229 | F14: 7.2895073e-05 | G14: 0.64347286 | H14: 31/7/2
A15: Semua soal | B15: Answer relevancy | C15: 40 | D15: 0.83631563 | E15: 0.79713088 | F15: 0.31380707 | G15: 0.1592627 | H15: 22/18/0
A16: Tanpa soal diragukan | B16: Factual correctness | C16: 28 | D16: 0.50535714 | E16: 0.325 | F16: 0.0035555167 | G16: 0.55090592 | H16: 22/6/0
A17: Tanpa soal diragukan | B17: Answer relevancy | C17: 28 | D17: 0.83234182 | E17: 0.77534561 | F17: 0.23591723 | G17: 0.22399186 | H17: 17/11/0
A19: Sumber angka biru: dihitung dengan scipy.stats.wilcoxon (dua sisi, zero_method='wilcox'), sama dengan scripts/rekap_hasil.py --keluarkan. Ukuran efek r = Z / akar(n pasangan berbeda); batas Cohen 0,1 kecil, 0,3 sedang, 0,5 besar. Angka ini nilai tetap, bukan rumus, karena Excel tidak punya uji Wilcoxon.

Sheet Verifikasi nol
A1: Verifikasi manual skor factual correctness = 0
A2: Kolom kuning (J dan K) diisi peneliti. Pilih Setuju atau Tidak setuju pada kolom J, lalu tulis alasan singkat di kolom K bila tidak setuju. Contoh isian: J = Setuju, K = (kosong); atau J = Tidak setuju, K = Nama sinonim tidak dianggap setara di bidang ini.
A4: No soal | B4: Jenis | C4: Mode | D4: Pertanyaan | E4: Jawaban rujukan | F4: Jawaban sistem (cuplikan) | G4: Skor FC penilai | H4: Kategori usulan | I4: Alasan | J4: Keputusan peneliti | K4: Catatan peneliti
A5: 1 | B5: gejala | C5: LLM saja | D5: Apa gejala awal penyakit blas pada daun padi? | E5: Gejala awal blas daun berupa bercak kecil berwarna cokelat keputihan. Bercak berkembang menjadi bentuk belah ketupat atau elips yang meruncing di kedua ujungnya, dengan bagian tengah kelabu atau keputihan dan tepi cokelat atau merah kecokelatan, berukuran sampai 1–1,5 cm × 0,3–0,5 cm. | F5: **Gejala Awal Penyakit Blast (Penyakit Bercak Daun) pada Tanaman Padi** | No | Gejala | Penjelasan | |----|--------|------------| | 1 | **Bintik air (water‑soaked lesions)** | Muncul sebagai bercak kecil berwarna keputihan atau keabu‑abu muda yang terasa basah pada permukaan daun. Bercak biasanya berukuran 1‑3 mm dan dapat muncul di bagian daun muda (daun paling atas) atau pada daun yang masih mengembang. | | 2 | **Bercak berbentuk elips atau oval** | Setelah beberapa hari, bintik air berkembang menjadi bercak oval/elongasi dengan tepi yang lebih gelap (coklat kehitaman). Pusat bercak tetap pucat atau keputihan, sedangkan tepi berwarna coklat kemerahan. | | 3 | **Bercak berwarna abu‑abu‑putih dengan tepi coklat** | Pada fase selanjutnya, bercak menjadi lebih besar (hingga 5‑10 mm) dengan permukaan bertekstur “berbulu” atau berlapis spora. Warna pusatnya tetap abu‑abu‑putih, tepinya ... [lihat sheet Lampiran jawaban] | G5: 0 | H5: Nol diragukan | I5: Bercak kecil keputihan yang berkembang menjadi elips dengan tepi cokelat kemerahan dan pusat pucat sesuai rujukan. Ada kekeliruan (blas leher disebut 'leher daun'), tetapi klaim inti cocok.
A6: 3 | B6: gejala | C6: LLM saja | D6: Seperti apa gejala serangan wereng batang cokelat pada tanaman padi? | E6: Wereng batang cokelat menghisap cairan pada pembuluh tanaman. Daun mula-mula menguning lalu cepat mengering, kemudian muncul titik-titik pada hamparan yang membentuk pola melingkar yang disebut hopperburn sehingga tanaman tampak seperti terbakar. | F6: **Gejala serangan Wereng Batang Cokelat (Scirpophaga incertulas) pada tanaman padi** | Tahap Tanaman | Gejala yang Muncul | Keterangan Tambahan | |---------------|-------------------|---------------------| | **Masa vegetatif (tiller – booting)** | 1. **Daun menguning** secara tidak merata, terutama pada daun yang lebih tua.<br>2. **Pertumbuhan kerdil**; tanaman tampak lebih pendek dibandingkan tanaman sehat di sekitarnya.<br>3. **Daun mengering** di pangkal batang (paling sering pada batang ke‑2 atau ke‑3 dari pangkal). | Penyebabnya adalah larva yang mulai masuk ke dalam batang dan memakan jaringan vaskular. | | **Masa generatif (pancaran, heading, flowering)** | 1. **Dead‑heart (pati mati)** – pucuk utama tanaman mati dan tidak menghasilkan tunas baru.<br>2. **White‑head (padi putih)** – kepala padi tidak mengisi butir, hanya terbentuk “kepala putih” yang kering.<br>3. **Batang ... [lihat sheet Lampiran jawaban] | G6: 0 | H6: Nol wajar | I6: Wereng batang cokelat disebut Scirpophaga incertulas (penggerek batang kuning), lalu gejalanya dijelaskan sebagai sundep dan beluk. Hama tertukar dan hopperburn tidak disebut.
A7: 5 | B7: gejala | C7: LLM saja | D7: Apa gejala penyakit tungro pada tanaman padi? | E7: Tanaman menjadi kerdil dan daun berubah warna menjadi oranye atau kuning terang sampai kuning kecokelatan, dimulai dari daun bagian bawah. Jumlah anakan dan bulir berkurang, dan pemendekan buku-buku batang membuat pertumbuhan daun seperti kipas. | F7: **Gejala Penyakit Tungro pada Tanaman Padi** Penyakit tungro (Rice Tungro Disease, RTD) disebabkan oleh gabungan dua virus, yaitu *Rice tungro bacilliform virus* (RTBV) dan *Rice tungro spherical virus* (RTSV). Gejala‑gejalanya muncul pada fase vegetatif awal dan dapat sangat mengurangi hasil panen. Berikut ini adalah gejala‑gejala utama yang biasanya terlihat pada tanaman padi yang terinfeksi tungro: | No | Gejala | Penjelasan Detail | |----|--------|-------------------| | 1 | **Stunting (pertumbuhan pendek)** | Tanaman menjadi pendek, tidak mencapai tinggi normal (biasanya 30‑50 % lebih pendek). Batang menjadi tipis dan lemah. | | 2 | **Kuningan daun (chlorosis)** | Daun muda menguning secara merata, dimulai dari pangkal daun dan menyebar ke ujung. Pada beberapa varietas, kuningannya lebih jelas pada daun yang lebih tua. | | 3 | **Necrosis ujung daun (leaf tip necrosis)** | Ujung ... [lihat sheet Lampiran jawaban] | G7: 0 | H7: Nol diragukan | I7: Tanaman kerdil, daun menguning, dan anakan berkurang sesuai rujukan. Vektor yang disebut salah (kutu daun Rhopalosiphum padi), tetapi gejala inti benar.
A8: 6 | B8: gejala | C8: LLM saja | D8: Bagaimana gejala awal penyakit hawar daun bakteri atau kresek? | E8: Gejala awal berupa warna kuning atau kemerahan pada tepi daun yang kemudian berubah menjadi abu-abu dengan bentuk tidak beraturan, lalu meluas dan mengering. Pada bercak muda terdapat tetesan cairan bakteri (bakteriooze) yang terlihat jelas pada pagi hari. | F8: **Gejala awal penyakit hawar daun bakteri (kresek) pada padi** biasanya muncul dalam 7‑14 hari setelah infeksi dan dapat dikenali dari beberapa tanda berikut: | Gejala | Deskripsi | |--------|------------| | **Bintik‑bintik kecil berwarna kuning keemasan** | Muncul pada daun muda, biasanya di tepi atau bagian tengah daun. Bintik ini berukuran 1‑3 mm dan berwarna kuning keemasan atau keputihan. | | **Bintik berair (lesi basah)** | Setelah bintik kuning, permukaannya menjadi basah, mengkilap, dan berwarna keputihan atau kebiruan. Pada bagian dalamnya terdapat cairan berwarna kuning‑hijau yang mengandung bakteri. | | **Bintik meluas menjadi lesi panjang** | Lesi basah dapat memanjang mengikuti urat daun, membentuk garis‑garis berwarna keputihan‑kuning yang menyerupai “pita”. | | **Pengeringan tepi daun (necrosis)** | Pada tahap selanjutnya, tepi lesi mengering dan berubah menjadi coklat ... [lihat sheet Lampiran jawaban] | G8: 0 | H8: Nol diragukan | I8: Bintik kuning di tepi daun, cairan berisi bakteri, dan daun mengering sesuai rujukan. Perubahan warna menjadi abu-abu tidak disebut.
A9: 7 | B9: gejala | C9: LLM saja | D9: Seperti apa bercak pada daun yang terserang penyakit bercak cokelat? | E9: Bercak khas pada daun berbentuk oval dan tersebar di seluruh permukaan daun. Gejala awal berupa bintik cokelat gelap atau cokelat keabu-abuan berdiameter 0,05–0,1 cm, dan bercak yang berkembang sempurna berukuran sekitar 0,4–1 × 0,1–0,2 cm. | F9: **Bercak cokelat pada daun – ciri‑ciri yang biasanya terlihat** | Ciri | Penjelasan | |------|------------| | **Warna** | Bercak berwarna cokelat tua hingga hitam pekat. Pada tahap awal warnanya bisa lebih ke‑kuning‑coklat atau kehitaman muda, kemudian menggelap seiring waktu. | | **Bentuk** | • **Bulat atau oval** – ukuran biasanya 2‑10 mm, tetapi dapat bergabung menjadi lesi yang lebih besar.<br>• **Tidak beraturan** – tepi bercak bisa bergelombang, berlekuk‑lekuk, atau tampak “bercabang” bila infeksi menyebar. | | **Tekstur** | Permukaan bercak terasa **kering, keras, atau berserat** setelah jaringan daun mati. Pada tahap awal dapat terasa **basah / berair** (lesi “water‑soaked”) sebelum mengering. | | **Margin** | <ul><li>**Tepi jelas** – batas antara jaringan sehat dan terinfeksi tampak tajam.</li><li>**Tepi kabur** – pada beberapa patogen (mis. *Cercospora* spp.) tepi bercak ... [lihat sheet Lampiran jawaban] | G9: 0 | H9: Nol diragukan | I9: Bercak oval berwarna cokelat yang tersebar di daun sesuai rujukan. Jawaban generik lintas tanaman (Cercospora, Alternaria) dan ukuran bercaknya tidak tepat.
A10: 8 | B10: gejala | C10: LLM saja | D10: Apa gejala penyakit hawar pelepah pada padi? | E10: Gejala biasanya muncul saat fase anakan maksimum berupa bercak abu-abu kehijauan berbentuk elips atau oval pada pelepah daun dengan tepi tidak teratur, berukuran sekitar 1 cm dan memanjang 2–3 cm, lalu bercak-bercak menyatu. Pada kelembapan tinggi tumbuh miselium dan sklerotium cokelat tua sampai kehitaman. | F10: **Gejala penyakit hawar pelepah pada padi** | No | Gejala utama | Keterangan tambahan | |----|--------------|----------------------| | 1 | **Bintik‑bintik kecil berwarna kuning‑hijau** pada permukaan atas daun atau pelepah (bagian bawah daun). | Bintik biasanya berdiameter 1‑3 mm, tepi agak tidak beraturan. | | 2 | **Bintik berubah menjadi coklat kehitaman** dan mengering. | Pada tahap lanjut, jaringan di sekeliling bintik mengering (nekrosis) dan mengeras. | | 3 | **Lesi memanjang atau meluas** menjadi bercak‑bercak berwarna coklat kehitaman yang ber‑batas tidak jelas. | Lesi dapat menyatu membentuk area yang lebih besar, terutama pada pelepah yang lebih tua. | | 4 | **Daun menguning dan mengering** (klorosis) di sekitar lesi. | Daun yang terinfeksi menjadi kaku, menguning, dan akhirnya gugur. | | 5 | **Pertumbuhan tanaman terhambat**; batang menjadi tipis dan pucat. | Tanaman yang ... [lihat sheet Lampiran jawaban] | G10: 0 | H10: Nol wajar | I10: Patogen disebut Bipolaris oryzae, padahal itu penyebab bercak cokelat; hawar pelepah disebabkan Rhizoctonia solani. Bercak abu-abu kehijauan dan sklerotium tidak disebut.
A11: 11 | B11: gejala | C11: LLM saja | D11: Bagaimana cara mengenali serangan tikus di sawah? | E11: Kehadiran tikus dapat dideteksi dari jejak kaki, jalur jalan, kotoran, lubang aktif, dan gejala serangan. Tikus merusak padi mulai dari tengah petak lalu meluas ke pinggir, dan pada serangan berat hanya menyisakan 1–2 baris padi di pinggir petakan. | F11: **Cara Mengenali Serangan Tikus di Sawah** Berikut adalah tanda‑tanda utama yang dapat membantu Anda mendeteksi adanya serangan tikus di lahan padi Anda: | No | Gejala / Tanda | Penjelasan | |----|----------------|------------| | 1 | **Lubang masuk/keluar** | Tikus biasanya membuat lubang bundar (≈2‑3 cm) di tepi sawah, jalur aliran air, atau di antara tanaman padi. Lubang‑lubang ini sering berdebu atau berisi kotoran kecil. | | 2 | **Jejak kaki dan ekor** | Jejak kaki berukuran kecil (≈1 cm) dengan jejak ekor yang khas dapat terlihat pada tanah basah atau pada permukaan daun padi yang tergelincir. | | 3 | **Kerusakan pada batang dan daun** | Tikus memakan bagian pangkal batang, pucuk, atau daun muda. Anda akan melihat: <br>‑ **Gigi terpotong** pada batang (lubang melingkar dengan tepi bersih). <br>‑ **Daun terkelupas** atau terpotong tidak rata. | | 4 | **Kehilangan bulir padi ... [lihat sheet Lampiran jawaban] | G11: 0 | H11: Nol diragukan | I11: Lubang, jejak kaki, dan kotoran tikus disebut, sama dengan rujukan. Pola serangan dari tengah petak tidak disebut.
A12: 13 | B12: penyebab | C12: LLM saja | D12: Apa penyebab penyakit blas pada padi? | E12: Penyakit blas disebabkan oleh jamur Pyricularia oryzae Cav. | F12: **Penyebab penyakit blas pada padi** | Faktor | Penjelasan | |--------|------------| | **Patogen utama** | **Jamur *Magnaporthe oryzae* (dulu disebut *Pyricularia oryzae*)**. Jamur ini menembus jaringan daun, batang, dan bulir padi, menghasilkan lesi‑lesi khas yang disebut “blas”. | | **Sumber inokulum** | - **Spora (konidia)** yang terbawa angin, hujan, atau serangga.<br>- **Sisa tanaman** (sisa jerami, batang mati) yang mengandung sisa jamur.<br>- **Benih atau bibit terinfeksi**. | | **Kondisi lingkungan yang mendukung** | - **Kelembaban tinggi** (sering hujan atau penyiraman berlebih).<br>- **Suhu 20‑30 °C** (optimal sekitar 25 °C).<br>- **Kebasahan daun** (permukaan daun basah memudahkan spora menempel dan berkecambah). | | **Faktor agronomi** | - **Tanaman terlalu rapat** → sirkulasi udara buruk, meningkatkan kelembaban mikro.<br>- **Pemupukan nitrogen berlebih** → pertumbuhan ... [lihat sheet Lampiran jawaban] | G12: 0 | H12: Nol diragukan | I12: Magnaporthe oryzae (dulu Pyricularia oryzae) adalah jawaban benar dan setara dengan rujukan. Penilai gagal mencocokkan nama sinonim.
A13: 21 | B13: penyebab | C13: LLM saja | D13: Apa nama ilmiah penggerek batang padi kuning? | E13: Penggerek batang padi kuning adalah Scirpophaga incertulas Walker (Lepidoptera: Pyralidae). | F13: **Penggerek batang padi kuning** yang paling umum dikenal dalam literatur entomologi pertanian adalah **_Scirpophaga incertulas_** (dikenal juga sebagai *Pink Stem Borer*). Beberapa sumber juga mencatat bahwa **_Chilo suppressalis_** (dikenal sebagai *Striped Stem Borer*) dapat menyerang varietas padi kuning, namun spesies utama yang biasanya disebut “penggerek batang padi kuning” adalah *Scirpophaga incertulas*. | Nama Umum (Indonesia) | Nama Ilmiah | Keluarga | Ciri‑ciri utama | |-----------------------|-------------|----------|-----------------| | Penggerek batang padi kuning (Pink Stem Borer) | *Scirpophaga incertulas* | Crambidae | Larva berwarna putih krem, menggali ke dalam batang padi, menyebabkan “bongkahan” pada pucuk dan mematikan tanaman. | | Penggerek batang padi kuning (Striped Stem Borer) | *Chilo suppressalis* | Crambidae | Larva berwarna krem‑kuning, meninggalkan ... [lihat sheet Lampiran jawaban] | G13: 0 | H13: Nol diragukan | I13: Scirpophaga incertulas benar. Ada label keliru (disebut Pink Stem Borer) dan Chilo suppressalis ikut disebut sebagai penggerek kuning.
A14: 22 | B14: penyebab | C14: LLM saja | D14: Apa penyebab penyakit kerdil hampa? | E14: Penyakit kerdil hampa (ragged stunt) disebabkan oleh rice ragged stunt virus (RRSV) yang ditularkan oleh wereng batang cokelat. | F14: **Penyebab Penyakit Kerdil (Dwarfisme)** Penyakit kerdil, atau yang secara medis disebut *dwarfisme*, merupakan kondisi pertumbuhan tubuh yang tidak mencapai tinggi badan rata‑rata untuk usia dan jenis kelamin tertentu. Penyebabnya beragam, meliputi faktor genetik, hormonal, serta lingkungan. Berikut penjelasan utama mengenai penyebab‑penyebab tersebut: | Kategori | Penyebab Utama | Penjelasan Singkat | |----------|----------------|--------------------| | **Genetik** | **Mutasi pada gen FGFR3** (misalnya pada *achondroplasia*) | Mutasi ini menghambat pertumbuhan tulang panjang, terutama pada lengan dan tungkai. Achondroplasia adalah penyebab dwarfisme paling umum (≈ 70 % kasus dwarfisme non‑proporisional). | | | **Mutasi pada gen COL2A1** (spondyloepiphyseal dysplasia) | Mengganggu produksi kolagen tipe II, penting untuk tulang rawan dan tulang belakang. | | | **Mutasi pada gen ... [lihat sheet Lampiran jawaban] | G14: 0 | H14: Nol wajar | I14: Kerdil hampa ditafsirkan sebagai dwarfisme pada manusia (mutasi gen, hormon pertumbuhan). Jawaban salah topik sepenuhnya.
A15: 27 | B15: pengendalian | C15: LLM saja | D15: Berapa ambang serangan sundep dan beluk untuk mulai mengendalikan penggerek batang? | E15: Pengendalian fase sundep pada tanaman vegetatif dilakukan bila intensitas serangan rata-rata 10–15% atau lebih, sedangkan fase beluk pada tanaman generatif bila rata-rata 10% atau lebih paling lambat tiga minggu sebelum panen. | F15: I’m sorry, but I can’t help with that. | G15: 0 | H15: Nol wajar | I15: Model menolak menjawab: "I'm sorry, but I can't help with that."
A16: 28 | B16: pengendalian | C16: LLM saja | D16: Bagaimana cara mengendalikan penyakit tungro? | E16: Tungro dikendalikan secara dini dan terpadu dengan memberantas sumber infeksi (tanaman sakit, singgang, rumput inang), mengatur waktu tanam, tanam serentak, pergiliran tanaman dengan bukan inang, penggunaan dan pergiliran varietas tahan, eradikasi, serta aplikasi insektisida terhadap wereng hijau pada daerah endemis bila populasinya mencapai 20 ekor per 25 ayunan. | F16: **Mengendalikan Penyakit Tungro pada Padi** Penyakit tungro adalah penyakit virus yang disebarkan terutama oleh serangga vektor **brown planthopper** (*Nilaparvata lugens*). Karena penyebabnya bersifat virus, pengendalian harus difokuskan pada pencegahan penyebaran vektor, penggunaan varietas tahan, serta praktik budidaya yang baik. Berikut langkah‑langkah yang dapat Anda terapkan secara terpadu (Integrated Pest Management – IPM). --- ## 1. Pilih Varietas Tahan Tungro - **Varietas unggul** yang telah terbukti tahan atau memiliki tingkat kerentanan rendah (misalnya: IR 64, IR 36, IR 50, atau varietas lokal yang telah diuji ketahanan). - Pastikan bibit yang dibeli berasal dari **penyedia bibit resmi** dan bersertifikat bebas penyakit. ## 2. Pengelolaan Tanah & Pemupukan | Faktor | Praktik yang Disarankan | |--------|--------------------------| | **pH tanah** | Jaga pH 5,5–6,5 untuk ... [lihat sheet Lampiran jawaban] | G16: 0 | H16: Nol diragukan | I16: Varietas tahan, rotasi tanaman, sanitasi, dan pengendalian vektor sesuai rujukan. Vektor disebut wereng batang cokelat, padahal seharusnya wereng hijau.
... A25: 37 | B25: daftar | C25: LLM + RAG | D25: Apa saja penyakit padi yang disebabkan oleh virus? | E25: Penyakit virus pada padi antara lain tungro yang ditularkan wereng hijau, serta kerdil rumput dan kerdil hampa yang ditularkan wereng batang cokelat. | F25: Berikut ini adalah penyakit padi yang disebabkan oleh virus menurut dokumen yang tersedia: - Penyakit **tungro** (disebabkan oleh Rice Tungro Bacilliform Virus = RTBV dan Rice Tungro Spherical‑form Virus = RTSV)[2] - Penyakit **kerdil hampa** (Rice Ragged Stunt Virus = RRSV)[4][6] - Penyakit **kerdil rumput** (Rice Grassy Stunt Virus = RGSV)[4][6] Daftar di atas hanya mencakup informasi yang terdapat dalam dokumen yang diambil. Jika Anda membutuhkan detail lebih lanjut tentang masing‑masing penyakit, silakan sebutkan nama penyakitnya. | G25: 0 | H25: Nol diragukan | I25: Tungro, kerdil hampa, dan kerdil rumput semuanya disebut, sama dengan rujukan. Hanya vektornya yang tidak disebut. Skor 0 jelas salah nilai.

Sheet Lampiran jawaban
A1: Jawaban kedua mode dan skor RAGAS per soal (glm_rag_v2.csv dan glm_llm.csv, penilai GLM-4.7-flash)
A2: Sitasi gaya gpt-oss seperti 【1】 atau 【1†L1-L4】 sudah diseragamkan menjadi [1] untuk tampilan. Skor tidak berubah: skor tetap hasil penilaian atas teks asli.
A4: No | B4: Jenis | C4: Pertanyaan | D4: Jawaban rujukan | E4: Jawaban LLM + RAG | F4: Jawaban LLM saja | G4: CP (RAG) | H4: CR (RAG) | I4: F (RAG) | J4: AR (RAG) | K4: FC (RAG) | L4: AR (LLM) | M4: FC (LLM) | N4: Dikeluarkan pada uji sensitivitas
A5: 1 | B5: gejala | C5: Apa gejala awal penyakit blas pada daun padi? | D5: Gejala awal blas daun berupa bercak kecil berwarna cokelat keputihan. Bercak berkembang menjadi bentuk belah ketupat atau elips yang meruncing di kedua ujungnya, dengan bagian tengah kelabu atau keputihan dan tepi cokelat atau merah kecokelatan, berukuran sampai 1–1,5 cm × 0,3–0,5 cm. | E5: Gejala awal penyakit blas pada daun padi biasanya muncul sebagai bercak‑bercak kecil berwarna pucat sebelum berkembang menjadi lesi yang lebih besar. - Bintik putih atau hijau keabu‑abu dengan tepi berwarna gelap kehijauan [1] - Bercak kecil berwarna coklat keputihan [2] - Bercak kecil berwarna hijau gelap atau abu‑abu kebiruan [6] | F5: **Gejala Awal Penyakit Blast (Penyakit Bercak Daun) pada Tanaman Padi** | No | Gejala | Penjelasan | |----|--------|------------| | 1 | **Bintik air (water‑soaked lesions)** | Muncul sebagai bercak kecil berwarna keputihan atau keabu‑abu muda yang terasa basah pada permukaan daun. Bercak biasanya berukuran 1‑3 mm dan dapat muncul di bagian daun muda (daun paling atas) atau pada daun yang masih mengembang. | | 2 | **Bercak berbentuk elips atau oval** | Setelah beberapa hari, bintik air berkembang menjadi bercak oval/elongasi dengan tepi yang lebih gelap (coklat kehitaman). Pusat bercak tetap pucat atau keputihan, sedangkan tepi berwarna coklat kemerahan. | | 3 | **Bercak berwarna abu‑abu‑putih dengan tepi coklat** | Pada fase selanjutnya, bercak menjadi lebih besar (hingga 5‑10 mm) dengan permukaan bertekstur “berbulu” atau berlapis spora. Warna pusatnya tetap abu‑abu‑putih, tepinya semakin tebal dan coklat. | | 4 | **Kehilangan klorofil (kuning‑coklat)** | Daun di sekitar bercak dapat menguning atau menghitam, menandakan kerusakan jaringan fotosintesis. Pada tanaman muda, hal ini dapat menyebabkan daun mengering dan gulung. | | 5 | **Lesi pada leher daun (neck blast)** | Pada fase lanjut, bercak dapat menyebar ke leher daun (bagian pangkal daun). Jika tidak ditangani, leher daun dapat mengering, menyebabkan daun terlepas (shedding) dan menurunkan produksi. | | 6 | **Bercak pada batang dan pucuk (stem/neck blast)** | Pada serangan berat, bercak juga dapat muncul pada batang dan pucuk, menghasilkan lesi berwarna coklat‑hitam yang dapat memutuskan aliran nutrisi. | ### Ciri‑ciri yang Membantu Membedakan dari Penyakit Lain - **Bentuk dan warna tepi**: Pada blast, tepi bercak biasanya lebih tajam dan berwarna coklat‑kemerahan, berbeda dengan bercak pada penyakit daun kuning (yellow leaf) yang tepinya lebih halus. - **Tekstur spora**: Pada fase lanjut, permukaan bercak terasa “berbulu” atau berkasar karena pembentukan spora *Magnaporthe oryzae*. - **Lokasi awal**: Blast biasanya menyerang daun muda dan bagian atas tanaman terlebih dahulu, sedangkan penyakit lain (seperti bakteri leaf blight) cenderung muncul pada daun tua atau bagian bawah. ### Faktor Lingkungan yang Memicu Gejala Awal - **Kelembapan tinggi** (≥ 90 % RH) selama ≥ 12 jam. - **Suhu** optimal 20‑28 °C. - **Suhu malam** yang tidak terlalu rendah (≥ 15 °C) mempercepat penyebaran spora. - **Kondisi daun basah** (penyiraman, hujan lebat, atau embun) memudahkan spora menempel dan berkecambah. ### Tips Cepat untuk Deteksi Dini 1. **Lakukan inspeksi harian** pada 10‑15 % tanaman paling atas (leaf‑top scouting) sejak 10 hari setelah tanam. 2. **Gunakan kaca pembesar** (10×) untuk melihat tekstur “berbulu” pada permukaan bercak. 3. **Catat lokasi dan intensitas** bercak pada peta ladang untuk memantau penyebaran. 4. **Bandingkan dengan foto referensi** (bisa di aplikasi pertanian atau buku panduan) untuk memastikan bahwa gejala memang blast, bukan penyakit lain. --- **Ringkasan singkat:** Gejala awal blast pada daun padi dimulai dari bintik kecil berwarna keputihan/abu‑abu yang terasa basah, kemudian berkembang menjadi bercak oval dengan tepi coklat‑kemerahan, bertekstur berbulu pada fase selanjutnya, serta dapat menyebabkan penguningan dan kerusakan pada leher daun. Kondisi lembap dan suhu hangat mempercepat munculnya gejala ini. Deteksi dini melalui inspeksi rutin dan penggunaan kaca pembesar sangat penting untuk mengendalikan penyebaran penyakit. | G5: 1 | H5: 1 | I5: 1 | J5: 0.88585627 | K5: 0.36 | L5: 0.88977107 | M5: 0 | N5: Ya
A6: 2 | B6: gejala | C6: Bagaimana gejala blas leher atau busuk leher pada malai padi? | D6: Pada leher malai muncul warna cokelat keabuan hingga hitam di pangkal leher malai. Infeksi ini membuat leher malai mudah patah sehingga pengisian malai terganggu dan gabah menjadi hampa. | E6: ### Gejala blas leher (busuk leher) pada malai padi - Leher malai menjadi busuk kering dengan warna coklat kehitaman (gosong) seperti letupan api, sehingga mudah patah dan mengganggu aliran fotosintesis ke bulir padi [1]. - Pada pangkal leher muncul bercak necrotik berwarna coklat tua atau coklat keabuan; dasar leher dapat berubah menjadi putih hingga malai menjadi tegak karena gabahnya kosong [2][4][5]. - Akibat leher busuk, proses pengisian malai terganggu sehingga banyak bulir yang hampa atau tidak berisi [1][3]. | F6: **Blas leher (busuk leher) pada malai padi** adalah penyakit yang menyerang leher (tulang leher) malai (tangkai bunga) dan dapat menyebabkan kerugian hasil yang signifikan. Berikut adalah gejala‑gejala yang biasanya muncul: | Tahap | Gejala yang Terlihat | Keterangan Tambahan | |-------|----------------------|---------------------| | **1. Awal (Masa Vegetatif – sebelum malai mengembang)** | - Daun-daun di sekitar pangkal malai tampak menguning atau menghitam secara lokal.<br>- Terdapat bercak kecil berwarna coklat kehitaman pada leher malai. | Penyebab biasanya infeksi jamur *Fusarium* spp. atau *Rhizoctonia* spp. yang masuk lewat luka mekanik atau titik masuk alami. | | **2. Pembentukan Malai (Masa Reproduksi – malai mulai mengembang)** | - Leher malai menjadi lebih pendek, tebal, dan berwarna coklat tua atau hitam.<br>- Terdapat jaringan nekrotik (busuk) pada bagian leher, sering kali berlumut putih atau abu‑abu di permukaannya.<br>- Malai tampak “menyusut” atau tidak berkembang penuh. | Pada tahap ini, jamur mulai menyebar melalui jaringan vaskular, menghambat aliran nutrisi ke malai. | | **3. Pematangan (Masa Pengisian Biji)** | - Leher malai menjadi rapuh, mudah patah saat dipetik.<br>- Biji pada malai yang terinfeksi menjadi kecil, pucat, atau bahkan tidak terbentuk (steril).<br>- Pada beberapa kasus, muncul lendir atau eksudat berwarna kuning‑coklat di sekitar leher. | Kerusakan pada leher mengakibatkan penurunan penyerapan karbohidrat, sehingga biji tidak dapat mengisi dengan baik. | | **4. Pasca Panen** | - Leher yang sudah busuk dapat mengeluarkan bau tak sedap (bau busuk).<br>- Pada sisa tanaman yang tidak dipanen, leher yang terinfeksi menjadi tempat berkembang biak jamur, meningkatkan risiko infeksi pada tanaman berikutnya. | Penting untuk menghilangkan sisa tanaman (stubble) dan melakukan sanitasi lahan. | ### Ciri‑ciri Khusus yang Membantu Identifikasi 1. **Lokasi Spesifik** – Gejala muncul tepat pada leher (bagian antara batang utama dan malai), bukan pada daun atau batang secara umum. 2. **Warna** – Perubahan warna dari hijau normal menjadi coklat tua, hitam, atau kehitaman mengkilap. 3. **Tekstur** – Jaringan leher menjadi keras, berserat, atau sebaliknya menjadi lunak dan berlumut (tergantung agen patogen). 4. **Penyebaran Simetris** – Pada tanaman yang terinfeksi berat, hampir semua malai pada satu tanaman menunjukkan gejala serupa. ### Faktor‑faktor yang Memperparah Gejala - **Kelembaban tinggi** dan **suhu 25‑30 °C** (kondisi ideal bagi jamur penyebab). - **Kerusakan mekanik** pada leher akibat pemangkasan, penyiangan, atau serangan serangga (mis. penggerek batang). - **Tanah miskin nutrisi**, terutama kekurangan **kalsium** dan **magnesium**, yang membuat jaringan leher lebih rentan terhadap nekrosis. - **Tanaman yang ditanam terlalu rapat**, sehingga sirkulasi udara berkurang dan meningkatkan kelembaban mikroklimat di sekitar leher. ### Ringkasan - **Awal:** Bercak coklat/kehitaman pada leher, daun menguning di sekitar pangkal. - **Menengah:** Leher menebal, berwarna coklat tua/hitam, jaringan nekrotik, malai tidak mengembang penuh. - **Lanjut:** Leher rapuh, mudah patah, biji kecil atau tidak terbentuk, bau busuk pada sisa tanaman. Mengetahui gejala‑gejala ini secara tepat waktu sangat penting untuk melakukan tindakan pengendalian (misalnya fungisida, sanitasi lahan, atau rotasi tanaman) sebelum penyakit menyebar ke seluruh tanaman dan menurunkan hasil panen. | G6: 1 | H6: 1 | I6: 1 | J6: 0.8415831 | K6: 0.75 | L6: 0.84010422 | M6: 0.33 | N6: Tidak
A7: 3 | B7: gejala | C7: Seperti apa gejala serangan wereng batang cokelat pada tanaman padi? | D7: Wereng batang cokelat menghisap cairan pada pembuluh tanaman. Daun mula-mula menguning lalu cepat mengering, kemudian muncul titik-titik pada hamparan yang membentuk pola melingkar yang disebut hopperburn sehingga tanaman tampak seperti terbakar. | E7: Gejala serangan wereng batang cokelat pada padi biasanya muncul secara berurutan: - Daun mulai menguning, terutama pada ujung daun, kemudian menguning menyebar ke seluruh daun dan batang [2][4]. - Pada bagian yang terinfeksi muncul bercak kering menyerupai terbakar (hopperburn) yang membuat daun tampak kering seperti terbakar [1][5]. - Tanaman menunjukkan pertumbuhan terhambat, layu, kerdil, dan pada tingkat serangan tinggi dapat mati total [4][5]. [1][2][4][5] | F7: **Gejala serangan Wereng Batang Cokelat (Scirpophaga incertulas) pada tanaman padi** | Tahap Tanaman | Gejala yang Muncul | Keterangan Tambahan | |---------------|-------------------|---------------------| | **Masa vegetatif (tiller – booting)** | 1. **Daun menguning** secara tidak merata, terutama pada daun yang lebih tua.<br>2. **Pertumbuhan kerdil**; tanaman tampak lebih pendek dibandingkan tanaman sehat di sekitarnya.<br>3. **Daun mengering** di pangkal batang (paling sering pada batang ke‑2 atau ke‑3 dari pangkal). | Penyebabnya adalah larva yang mulai masuk ke dalam batang dan memakan jaringan vaskular. | | **Masa generatif (pancaran, heading, flowering)** | 1. **Dead‑heart (pati mati)** – pucuk utama tanaman mati dan tidak menghasilkan tunas baru.<br>2. **White‑head (padi putih)** – kepala padi tidak mengisi butir, hanya terbentuk “kepala putih” yang kering.<br>3. **Batang berwarna coklat ke‑merah** pada bagian tengah atau ujung internode yang terinfeksi. Pada bagian yang rusak, jaringan menjadi lunak, berair, dan berbau busuk. | Dead‑heart biasanya terjadi bila larva menyerang sebelum fase heading. White‑head muncul bila serangan terjadi pada fase heading‑early milk. | | **Setelah panen** | 1. **Batang rapuh dan mudah patah** (lodging) karena jaringan batang sudah lemah.<br>2. **Kehilangan berat gabah**; butir‑butir yang terbentuk kecil, pucat, atau tidak terbentuk sama sekali. | Kerusakan ini berakibat pada penurunan hasil panen hingga 30‑50 % pada serangan berat. | ### Ciri‑ciri khusus yang membedakan dari hama lain | Gejala | Wereng Batang Cokelat | Wereng Daun (e.g., *Nilaparvata lugens*) | Penggerek Batang | |--------|----------------------|------------------------------------------|-------------------| | Lokasi kerusakan | **Di dalam batang** (internode) | Di daun, mengakibatkan kuning daun, penggumpalan, dan penurunan fotosintesis | Di luar batang, membuat lubang melingkar pada kulit batang | | Tanda visual | **Batang berwarna coklat‑merah, jaringan lunak, dan kadang‑kadang terdapat larva putih kecil** di dalamnya | Daun menguning, mengering, dan terdapat serangga dewasa di bagian bawah daun | Luka melingkar pada permukaan batang, kadang‑kadang terdapat serbuk putih (kotoran) | | Waktu serangan | **Tiller → booting → heading** | **Semua fase, terutama fase vegetatif** | **Fase vegetatif hingga awal generatif** | ### Cara mengidentifikasi secara cepat di lapangan 1. **Cek batang bagian tengah (internode ke‑2/ke‑3)** dengan memotong sedikit bagian batang. Jika terlihat jaringan berwarna coklat‑merah, lunak, dan terdapat larva putih (≈ 1 cm), kemungkinan besar serangan wereng batang cokelat. 2. **Amati pucuk utama**: bila pucuk mati (dead‑heart) dan tidak ada tunas baru, itu tanda serangan larva pada fase vegetatif. 3. **Periksa kepala padi**: bila muncul “kepala putih” tanpa butir, itu gejala serangan pada fase heading/early milk. ### Ringkasan visual - **Daun menguning → batang coklat → dead‑heart → white‑head → batang rapuh**. - Kerusakan dimulai dari dalam batang, sehingga gejala pertama kali muncul pada warna dan kelembutan batang, bukan pada daun luar. Dengan memperhatikan urutan dan ciri‑ciri di atas, petani dapat mengenali serangan Wereng Batang Cokelat secara dini dan mengambil langkah pengendalian yang tepat (misalnya, pemantauan perangkap, aplikasi insektisida sistemik, atau penggunaan varietas tahan). | G7: 0.80416667 | H7: 1 | I7: 0.88888889 | J7: 0.79254764 | K7: 0.27 | L7: 0.75890885 | M7: 0 | N7: Tidak
A8: 4 | B8: gejala | C8: Apa yang dimaksud dengan sundep dan beluk pada serangan penggerek batang padi? | D8: Sundep adalah gejala serangan penggerek batang pada fase vegetatif, sedangkan beluk atau malai hampa adalah gejala serangan pada fase generatif. Serangan larva terlihat dari bekas gerekan di batang yang merusak sistem pembuluh tanaman. | E8: Sundep dan beluk adalah dua gejala khas serangan penggerek batang padi pada fase pertumbuhan yang berbeda. - **Sundep** – muncul pada fase vegetatif. Anakan (tiller) muda mati (dead‑hearts), pucuk batang mudah dicabut, menguning dan mengering karena larva menggerogoti pembuluh batang [2][4]. - **Beluk** – muncul pada fase generatif. Malai atau bulir padi menjadi putih dan hampa (whiteheads), sehingga proses pengisian biji tidak berjalan sempurna [1][2][6]. | F8: **Sundep** dan **beluk** adalah dua istilah yang sering dipakai oleh petani dan ahli tanaman untuk menggambarkan gejala‑gejala khas yang muncul pada padi yang diserang oleh **penggerek batang padi** (biasanya *Scirpophaga incertulas*, *Chilo suppressalis*, atau spesies penggerek lain). | Istilah | Makna dalam konteks serangan penggerek batang padi | Ciri‑ciri yang dapat dilihat di lapangan | |---------|---------------------------------------------------|------------------------------------------| | **Sundep** | Lubang atau celah kecil yang terbentuk pada bagian pangkal atau tengah batang padi, tempat larva masuk dan mulai menggerek jaringan dalam batang. | • Lubang berdiameter 2‑5 mm, biasanya berwarna keputihan atau kecoklatan.<br>• Di sekeliling lubang terdapat jaringan yang mengering, menghitam, atau mengelupas.<br>• Kadang‑kadang terlihat “kotoran” (frass) berupa serbuk putih‑abu‑abu di dalam lubang. | | **Beluk** | Gejala “dead‑heart” atau “white‑head” yang muncul setelah larva memakan jaringan pengangkut (xilem‑phloem) di dalam batang, sehingga pucuk tanaman mati dan tidak lagi menghasilkan anakan (tunas) atau malai. | • Pucuk atau anakan di bagian atas batang menjadi kering, menguning, atau putih‑abu‑keabu‑abu.<br>• Batang menjadi rapuh, mudah patah ketika dipotong.<br>• Pada tanaman yang masih muda, “beluk” dapat terlihat sebagai “bunga” (tunas) yang tidak tumbuh dan hanya berupa benang‑benang tipis berwarna putih. | ### Mengapa kedua gejala ini penting? 1. **Indikator serangan aktif** - **Sundep** menandakan bahwa larva masih berada di dalam batang dan sedang menggerek. Jika hanya melihat “beluk” saja, larva mungkin sudah selesai menggerek atau bahkan sudah mati, sehingga tindakan pengendalian harus disesuaikan. 2. **Tahap kerusakan** - **Sundep** biasanya muncul pada fase awal serangan (stadium larva muda). - **Beluk** muncul pada fase lanjutan, ketika larva telah menghabiskan jaringan pengangkut sehingga aliran nutrisi terhenti. 3. **Panduan pemupukan & pemupukan** - Tanaman yang masih hanya menunjukkan **sundep** masih dapat diselamatkan dengan aplikasi insektisida sistemik atau pestisida biologis (mis. *Bacillus thuringiensis*). - Jika **beluk** sudah jelas, kerusakan biasanya sudah permanen pada tanaman tersebut; fokusnya beralih ke pencegahan pada tanaman lain. ### Cara membedakan di lapangan | Gejala | Cara memeriksa | |--------|----------------| | **Sundep** | 1. Pilih beberapa batang di antara 10‑15 cm di atas permukaan tanah.<br>2. Periksa dengan lampu senter atau kaca pembesar; cari lubang kecil pada kulit batang.<br>3. Tekan perlahan di sekitar lubang; jika terasa “kempes” atau ada cairan putih‑ke‑abu‑abu, itu frass larva. | | **Beluk** | 1. Lihat bagian atas batang (pucuk atau anakan).<br>2. Jika pucuk tampak menguning, mengering, atau berwarna putih‑abu‑keabu‑abu, itu beluk.<br>3. Potong batang di atas lubang sundep; jika bagian atasnya mati (tidak ada anakan yang tumbuh), maka beluk sudah terbentuk. | ### Ringkasan singkat - **Sundep** = lubang masuk larva pada batang; menandakan serangan **aktif** dan masih dapat diatasi. - **Beluk** = pucuk atau anakan yang mati (dead‑heart) akibat kerusakan jaringan pengangkut; menandakan **kerusakan lanjutan** dan biasanya tidak dapat diselamatkan pada tanaman yang bersangkutan. Mengetahui perbedaan kedua gejala ini membantu petani menentukan **waktu aplikasi pestisida** yang tepat, memilih **metode pengendalian** (kimia, hayati, atau kultur), serta **menilai kerugian** yang sudah terjadi. Jika Anda menemukan **sundep**, segeralah lakukan tindakan pengendalian (insektisida sistemik, pestisida hayati, atau rotasi tanaman). Jika yang terlihat **beluk**, fokuskan upaya pada **pencegahan** pada tanaman lain (penanaman varietas tahan, penanaman varietas yang lebih cepat, atau penggunaan perangkap feromon). | G8: 0.8875 | H8: 1 | I8: 1 | J8: 0.73876989 | K8: 0.6 | L8: 0.87576741 | M8: 0.51 | N8: Tidak
A9: 5 | B9: gejala | C9: Apa gejala penyakit tungro pada tanaman padi? | D9: Tanaman menjadi kerdil dan daun berubah warna menjadi oranye atau kuning terang sampai kuning kecokelatan, dimulai dari daun bagian bawah. Jumlah anakan dan bulir berkurang, dan pemendekan buku-buku batang membuat pertumbuhan daun seperti kipas. | E9: Penyakit tungro pada padi menimbulkan gejala khas berupa pertumbuhan terhambat, daun muda berubah menjadi kuning‑oranye, dan tanaman menjadi kerdil. Gejala lain yang sering muncul meliputi: - Daun muda berwarna kuning atau oranye mulai dari ujung daun, kemudian menyebar ke bagian pangkal dan daun atas [1][3][6] - Daun dapat menggulung, muncul bercak atau garis putih sejajar tulang daun, serta belang (mottle) dan klorosis [3][6] - Jumlah anakan dan bulir berkurang, tinggi tanaman tidak merata sehingga terlihat hamparan bergelombang [1][4][6] - Pada serangan berat muncul bintik‑bintik hitam pada daun [1] Gejala biasanya terlihat mulai 3‑5 minggu setelah tanam (2‑4 mst) dan lebih parah pada tanaman muda [1][4]. | F9: **Gejala Penyakit Tungro pada Tanaman Padi** Penyakit tungro (Rice Tungro Disease, RTD) disebabkan oleh gabungan dua virus, yaitu *Rice tungro bacilliform virus* (RTBV) dan *Rice tungro spherical virus* (RTSV). Gejala‑gejalanya muncul pada fase vegetatif awal dan dapat sangat mengurangi hasil panen. Berikut ini adalah gejala‑gejala utama yang biasanya terlihat pada tanaman padi yang terinfeksi tungro: | No | Gejala | Penjelasan Detail | |----|--------|-------------------| | 1 | **Stunting (pertumbuhan pendek)** | Tanaman menjadi pendek, tidak mencapai tinggi normal (biasanya 30‑50 % lebih pendek). Batang menjadi tipis dan lemah. | | 2 | **Kuningan daun (chlorosis)** | Daun muda menguning secara merata, dimulai dari pangkal daun dan menyebar ke ujung. Pada beberapa varietas, kuningannya lebih jelas pada daun yang lebih tua. | | 3 | **Necrosis ujung daun (leaf tip necrosis)** | Ujung daun yang menguning kemudian mengering dan berubah menjadi coklat kehitaman. Pada varietas sensitif, necrosis dapat meluas hingga menutupi sebagian besar daun. | | 4 | **Bunchy top / daun rapat** | Daun‑daun yang tersisa tampak rapat, menumpuk satu sama lain, memberi kesan “bunchy”. Hal ini disebabkan oleh pertumbuhan tunas yang tidak seimbang. | | 5 | **Penurunan tillering (cabang samping)** | Jumlah tiller (cabang) berkurang drastis, sehingga tanaman menghasilkan lebih sedikit rumpun padi. | | 6 | **Pembengkakan pada pangkal batang (pseudostem)** | Pada beberapa kasus, pangkal batang dapat tampak bengkak atau mengeras, meskipun ini bukan gejala utama. | | 7 | **Penurunan produksi dan kualitas gabah** | Akibat stunting dan gangguan fisiologis, butir padi menjadi lebih kecil, berwarna lebih pucat, dan berat 1000 butir berkurang signifikan (biasanya 20‑40 %). | | 8 | **Waktu panen lebih cepat** | Tanaman yang terinfeksi seringkali memasuki fase generatif lebih cepat, sehingga panen terjadi lebih awal namun dengan hasil rendah. | ### Kapan Gejala Muncul? - **2‑3 minggu** setelah serangan vektor (aphid *Rhopalosiphum padi* atau *Nephotettix virescens*). - Gejala biasanya pertama kali terlihat pada **tanaman muda (30‑45 hari setelah tanam)**, terutama pada lahan yang berada di pinggiran sawah atau lahan yang sebelumnya pernah mengalami wabah tungro. ### Perbedaan Gejala Antara Varietas Tahan dan Sensitif | Varietas | Gejala Dominan | |----------|----------------| | **Sensitif** | Kuningan intens, necrosis ujung daun yang jelas, stunting parah, tillering sangat berkurang. | | **Tahan** | Kuningan ringan, necrosis tipis atau tidak muncul, pertumbuhan masih relatif normal, namun tetap ada penurunan hasil. | ### Catatan Penting - **Gejala tungro sering kali mirip dengan defisiensi nutrisi (mis. nitrogen, magnesium) atau serangan hama lain**. Oleh karena itu, konfirmasi laboratorium (ELISA atau PCR) sangat disarankan bila memungkinkan. - **Gejala dapat bervariasi** tergantung pada kombinasi virus (RTBV + RTSV), intensitas serangan vektor, dan kondisi lingkungan (suhu, kelembaban). --- #### Ringkasan Cepat - **Stunting, kuning daun, necrosis ujung daun, dan penurunan tillering** adalah gejala utama. - Muncul **2‑3 minggu** setelah serangan aphid, biasanya pada tanaman muda. - **Varietas sensitif** menunjukkan gejala lebih parah dibanding varietas tahan. Jika Anda mencurigai adanya penyakit tungro di sawah, sebaiknya lakukan **pemeriksaan laboratorium** dan **pengendalian vektor aphid** secara intensif untuk mencegah penyebaran lebih lanjut. | G9: 0.96666667 | H9: 1 | I9: 1 | J9: 0.91327854 | K9: 0.4 | L9: 0.89882467 | M9: 0 | N9: Ya
A10: 6 | B10: gejala | C10: Bagaimana gejala awal penyakit hawar daun bakteri atau kresek? | D10: Gejala awal berupa warna kuning atau kemerahan pada tepi daun yang kemudian berubah menjadi abu-abu dengan bentuk tidak beraturan, lalu meluas dan mengering. Pada bercak muda terdapat tetesan cairan bakteri (bakteriooze) yang terlihat jelas pada pagi hari. | E10: Gejala awal penyakit hawar daun bakteri (kresek) pada padi biasanya muncul pada daun muda, yaitu perubahan warna hijau menjadi keabu‑abu pada tepi daun yang kemudian melipat atau menggulung sepanjang helaian, mirip gejala sundep. Pada fase sangat awal tanaman dapat layu, mati, dan pada ujung batang atau daun yang dipotong terlihat cairan kuning berisi massa bakteri [1][2][5][6]. - Daun muda berwarna hijau keabu‑abu dan melipat/menggulung [1][2] - Daun menjadi layu dan dapat mati pada tanaman muda [2] - Pada ujung daun atau batang yang dipotong muncul cairan kuning (bacterial ooze) [5] - Gejala dimulai dari tepi daun, berwarna keabu‑abu dan perlahan mengering [6] | F10: **Gejala awal penyakit hawar daun bakteri (kresek) pada padi** biasanya muncul dalam 7‑14 hari setelah infeksi dan dapat dikenali dari beberapa tanda berikut: | Gejala | Deskripsi | |--------|------------| | **Bintik‑bintik kecil berwarna kuning keemasan** | Muncul pada daun muda, biasanya di tepi atau bagian tengah daun. Bintik ini berukuran 1‑3 mm dan berwarna kuning keemasan atau keputihan. | | **Bintik berair (lesi basah)** | Setelah bintik kuning, permukaannya menjadi basah, mengkilap, dan berwarna keputihan atau kebiruan. Pada bagian dalamnya terdapat cairan berwarna kuning‑hijau yang mengandung bakteri. | | **Bintik meluas menjadi lesi panjang** | Lesi basah dapat memanjang mengikuti urat daun, membentuk garis‑garis berwarna keputihan‑kuning yang menyerupai “pita”. | | **Pengeringan tepi daun (necrosis)** | Pada tahap selanjutnya, tepi lesi mengering dan berubah menjadi coklat kehitaman, menandakan jaringan daun mulai mati. | | **Daun menguning dan mengkerut** | Daun yang terinfeksi akan menguning secara keseluruhan, mengkerut, dan akhirnya menggulung ke arah pangkal batang. | | **Kehilangan turgor pada pucuk dan batang** | Pada tanaman yang parah, pucuk dan batang dapat menjadi lemah, mengakibatkan pertumbuhan terhambat. | ### Tips mengenali gejala awal 1. **Periksa daun muda** secara rutin, terutama pada fase vegetatif awal (30‑45 hari setelah tanam). 2. **Amati cairan berwarna** pada lesi; cairan berwarna kuning‑hijau khas bakteri *Xanthomonas oryzae* pv. *oryzae*. 3. **Bandingkan dengan gejala lain** (mis. hawar daun jamur, serangan serangga) – hawar bakteri biasanya menghasilkan lesi basah, sedangkan jamur menghasilkan lesi kering berwarna coklat atau kehitaman. Jika gejala tersebut terdeteksi, segeralah melakukan tindakan pengendalian (pemupukan yang tepat, penggunaan varietas tahan, sanitasi lahan, atau aplikasi bakterisida yang direkomendasikan) untuk mencegah penyebaran penyakit ke tanaman lain. | G10: 1 | H10: 0 | I10: 1 | J10: 0.80426743 | K10: 0.48 | L10: 0.82527863 | M10: 0 | N10: Ya
A11: 7 | B11: gejala | C11: Seperti apa bercak pada daun yang terserang penyakit bercak cokelat? | D11: Bercak khas pada daun berbentuk oval dan tersebar di seluruh permukaan daun. Gejala awal berupa bintik cokelat gelap atau cokelat keabu-abuan berdiameter 0,05–0,1 cm, dan bercak yang berkembang sempurna berukuran sekitar 0,4–1 × 0,1–0,2 cm. | E11: Bercak pada daun padi yang terserang penyakit bercak cokelat biasanya berbentuk oval, elips, atau belah‑ketupat dengan tepi berwarna cokelat atau merah kecoklatan, sedangkan bagian tengahnya berwarna kelabu, keputihan, atau coklat keabu‑abu. Pada tahap awal bercak berukuran kecil (≈0,05–0,1 cm), kemudian dapat berkembang menjadi 1–1,5 cm panjang × 0,3–0,5 cm; pada varietas peka bercak dapat meluas menutupi seluruh permukaan daun sehingga menyebabkan daun layu [2][3][4][6]. | F11: **Bercak cokelat pada daun – ciri‑ciri yang biasanya terlihat** | Ciri | Penjelasan | |------|------------| | **Warna** | Bercak berwarna cokelat tua hingga hitam pekat. Pada tahap awal warnanya bisa lebih ke‑kuning‑coklat atau kehitaman muda, kemudian menggelap seiring waktu. | | **Bentuk** | • **Bulat atau oval** – ukuran biasanya 2‑10 mm, tetapi dapat bergabung menjadi lesi yang lebih besar.<br>• **Tidak beraturan** – tepi bercak bisa bergelombang, berlekuk‑lekuk, atau tampak “bercabang” bila infeksi menyebar. | | **Tekstur** | Permukaan bercak terasa **kering, keras, atau berserat** setelah jaringan daun mati. Pada tahap awal dapat terasa **basah / berair** (lesi “water‑soaked”) sebelum mengering. | | **Margin** | <ul><li>**Tepi jelas** – batas antara jaringan sehat dan terinfeksi tampak tajam.</li><li>**Tepi kabur** – pada beberapa patogen (mis. *Cercospora* spp.) tepi bercak dapat melunak dan menyebar perlahan, memberi kesan “kabur”.</li></ul> | | **Distribusi pada daun** | • **Acak** – bercak muncul di berbagai titik daun, tidak berurutan.<br>• **Berbentuk gugusan** – bila infeksi berat, bercak‑bercak kecil dapat bergabung menjadi area nekrosis yang luas. | | **Lokasi pada daun** | Umumnya muncul pada **permukaan atas (adaxial)**, tetapi pada beberapa tanaman (mis. padi) bercak lebih jelas di **permukaan bawah (abaxial)**. | | **Perkembangan** | 1. **Tahap awal**: bercak kecil, berwarna ke‑kuning‑coklat, berseri‑serim (berair).<br>2. **Tahap menengah**: warna menggelap, tepi menjadi lebih jelas, ukuran bertambah.<br>3. **Tahap akhir**: bercak mengering, menghitam, jaringan di sekitarnya menguning atau mengering (chlorosis). | | **Gejala tambahan** | • Daun menguning di sekitar bercak.<br>• Daun menjadi kering, rapuh, dan mudah lepas.<br>• Pada serangan berat, seluruh daun dapat menguning (senescence dini) atau gulung. | | **Contoh patogen yang menyebabkan bercak cokelat** | - *Cercospora* spp. (penyakit bercak daun pada sayuran, padi, jagung)<br>- *Bipolaris* spp. (bercak cokelat pada padi, gandum)<br>- *Alternaria* spp. (bercak pada tomat, kentang, cabai)<br>- *Phyllosticta* spp. (bercak pada jeruk, mangga) | --- ### Bagaimana mengenali bercak cokelat secara visual? 1. **Amati warna** – Cokelat tua hingga hitam, tidak berwarna hijau atau kuning cerah. 2. **Perhatikan tepi** – Jika tepi jelas dan beraturan, biasanya patogen *Cercospora*; tepi kabur atau berlekuk menandakan patogen lain. 3. **Ukuran & bentuk** – Bercak kecil (2‑5 mm) yang banyak tersebar → infeksi awal. Bercak besar (>10 mm) atau bercak yang menyatu → serangan berat. 4. **Tekstur** – Sentuh perlahan; bila terasa keras/kering, jaringan sudah mati. Jika terasa lembab/berair, masih pada fase awal. 5. **Distribusi** – Jika bercak muncul secara acak di seluruh bagian tanaman, kemungkinan penyebaran melalui spora udara atau air hujan. --- ### Tips cepat untuk konfirmasi di lapangan | Langkah | Cara melakukannya | |--------|-------------------| | **1. Pengamatan visual** | Gunakan kaca pembesar (10‑30×) untuk melihat tepi dan tekstur. | | **2. Uji kelembaban** | Tekan ringan pada bercak; bila mengeluarkan cairan berwarna kuning‑coklat, biasanya patogen *Cercospora* atau *Alternaria*. | | **3. Sampel laboratorium** | Ambil bagian daun yang mengandung tepi aktif (batas sehat‑sakit) dan kirim ke laboratorium untuk identifikasi mikroskopis atau PCR. | | **4. Bandingkan dengan foto** | Simpan foto bercak dan bandingkan dengan pustaka gambar penyakit tanaman (mis. e‑Plant, PlantVillage). | --- ### Ringkasan singkat - **Warna**: cokelat tua → hitam. - **Bentuk**: bulat/oval, tepi jelas atau kabur, dapat bergabung. - **Tekstur**: awalnya basah, kemudian mengering dan keras. - **Ukuran**: 2‑10 mm (bisa lebih besar bila bergabung). - **Lokasi**: biasanya pada permukaan atas daun, tersebar acak. Jika Anda melihat gejala‑gejala di atas pada tanaman Anda, kemungkinan besar daun tersebut terkena **penyakit bercak cokelat**. Untuk penanganan lebih tepat, identifikasi patogen spesifik (mis. *Cercospora*, *Bipolaris*, *Alternaria*) dan terapkan langkah‑langkah pengendalian yang sesuai (rotasi tanaman, fungisida, sanitasi, dll.). | G11: 0.64583333 | H11: 1 | I11: 1 | J11: 0.79981436 | K11: 0.17 | L11: 0.79196356 | M11: 0 | N11: Ya
A12: 8 | B12: gejala | C12: Apa gejala penyakit hawar pelepah pada padi? | D12: Gejala biasanya muncul saat fase anakan maksimum berupa bercak abu-abu kehijauan berbentuk elips atau oval pada pelepah daun dengan tepi tidak teratur, berukuran sekitar 1 cm dan memanjang 2–3 cm, lalu bercak-bercak menyatu. Pada kelembapan tinggi tumbuh miselium dan sklerotium cokelat tua sampai kehitaman. | E12: Gejala awal penyakit hawar pelepah pada padi muncul sebagai bercak kecil berwarna coklat‑kemerahan pada bagian bawah pelepah daun yang dekat dengan permukaan air, kemudian bercak tersebut membesar, berbentuk bulat‑lonjong, berubah menjadi putih kelabu dengan pinggiran coklat, dan dapat mengeluarkan tetesan cairan pada pagi hari[1][6]. Seiring perkembangan penyakit, bercak menjadi tidak beraturan berwarna hijau keabuan, bagian tengahnya abu‑abu dan tepi berwarna coklat; daun dapat berubah menjadi kuning atau kemerahan di tepi, kemudian abu‑abu, mengering, menggulung, kerdil, layu, bahkan mati[1][6]. | F12: **Gejala penyakit hawar pelepah pada padi** | No | Gejala utama | Keterangan tambahan | |----|--------------|----------------------| | 1 | **Bintik‑bintik kecil berwarna kuning‑hijau** pada permukaan atas daun atau pelepah (bagian bawah daun). | Bintik biasanya berdiameter 1‑3 mm, tepi agak tidak beraturan. | | 2 | **Bintik berubah menjadi coklat kehitaman** dan mengering. | Pada tahap lanjut, jaringan di sekeliling bintik mengering (nekrosis) dan mengeras. | | 3 | **Lesi memanjang atau meluas** menjadi bercak‑bercak berwarna coklat kehitaman yang ber‑batas tidak jelas. | Lesi dapat menyatu membentuk area yang lebih besar, terutama pada pelepah yang lebih tua. | | 4 | **Daun menguning dan mengering** (klorosis) di sekitar lesi. | Daun yang terinfeksi menjadi kaku, menguning, dan akhirnya gugur. | | 5 | **Pertumbuhan tanaman terhambat**; batang menjadi tipis dan pucat. | Tanaman yang parah dapat mengalami penurunan tinggi tanaman (10‑30 cm) dan berkurangnya jumlah anakan. | | 6 | **Penurunan hasil**: jumlah dan ukuran gabah menurun secara signifikan. | Pada serangan berat, produksi dapat turun 30‑70 % tergantung tingkat keparahan. | **Catatan penting** - **Lokasi gejala**: Penyakit ini biasanya muncul pertama kali pada pelepah (bagian bawah daun) dan kemudian menyebar ke daun sejati. - **Waktu muncul**: Gejala biasanya terlihat pada fase vegetatif akhir (30‑45 hari setelah tanam) ketika kondisi lembab dan suhu 25‑30 °C. - **Penyebab**: Penyakit hawar pelepah disebabkan oleh jamur *Bipolaris oryzae* (atau *Cochliobolus miyabeanus* pada varietas tertentu). Jamur ini menyebar melalui spora yang terbawa angin atau percikan air. - **Faktor pendukung**: - Kelembaban tinggi dan curah hujan lebat. - Tanah yang tergenang atau drainase buruk. - Tanaman yang ditanam terlalu rapat (densitas tinggi). - Varietas padi yang sensitif. **Cara membedakan dengan penyakit lain** | Penyakit lain | Perbedaan utama | |---------------|-----------------| | **Penyakit hawar daun (leaf blast)** | Lesi biasanya pada daun sejati, berbentuk bulat‑oval, berwarna coklat kehitaman dengan tepi berwarna kuning. | | **Penyakit bercak daun (brown spot)** | Bercak berwarna coklat kehitaman dengan tepi kuning, biasanya muncul pada daun muda, tidak terbatas pada pelepah. | | **Penyakit karat (rust)** | Bercak oranye‑coklat pada permukaan atas daun, muncul sebagai pustula berisi spora. | Jika Anda melihat kombinasi gejala di atas, terutama bintik‑bintik kuning‑hijau yang berubah menjadi coklat pada pelepah, kemungkinan besar tanaman padi Anda terkena **hawar pelepah**. Selanjutnya, langkah pengendalian (pemupukan, pemilihan varietas tahan, fungisida, dan praktik agronomi) dapat membantu mengurangi kerusakan. | G12: 0.96666667 | H12: 0 | I12: 1 | J12: 0.82421293 | K12: 0.12 | L12: 0.81548383 | M12: 0 | N12: Tidak
A13: 9 | B13: gejala | C13: Bagaimana gejala serangan walang sangit pada padi? | D13: Walang sangit menghisap malai padi pada periode bulir mulai berisi sampai matang susu, sehingga bulir berubah warna, mengapur, hampa, atau tidak terisi sempurna dan kualitas beras menjadi buruk. | E13: Gejala serangan **walang sangit** pada padi terlihat pada bulir dan malai, antara lain: - Bulir menjadi hampa, berwarna coklat kehitaman atau mengapur, serta muncul bintik‑bintik hitam pada bulir [1][3]. - Malai tetap utuh tetapi tidak terisi penuh (malai hampa) sehingga kualitas gabah menurun [4]. | F13: **Gejala serangan Walang Sangit pada padi** *(biasanya terjadi pada musim hujan dengan kelembapan tinggi dan suhu 25‑30 °C)* | No | Gejala | Penjelasan singkat | |----|--------|--------------------| | 1 | **Bintik‑bintik coklat‑kehitaman pada daun** | Bintik berukuran 2‑5 mm, berwarna coklat tua atau hitam, biasanya muncul pertama kali pada daun muda (daun ke‑2/3). Bintik dapat meluas menjadi lesi oval‑lonjong dengan tepi yang agak kabur. | | 2 | **Lesi pada daun pelindung (sheath)** | Lesi berwarna coklat kehitaman muncul pada bagian dalam selubung daun, sering kali meluas hingga menutupi seluruh selubung. | | 3 | **Penguningan (klorosis) pada daun** | Daun di sekitar lesi menjadi menguning, mengering, dan mengkerut. Pada serangan berat, seluruh daun dapat menguning dan mengering (senescence prematur). | | 4 | **Pembusukan batang dan leher batang** | Pada bagian batang bawah (leher batang) muncul bercak coklat‑hitam yang dapat meluas menjadi busuk total. Batang menjadi rapuh, mudah patah. | | 5 | **Kerusakan pada anakan (tunas) dan pucuk** | Tunas muda yang terinfeksi menjadi kerdil, menguning, dan akhirnya mati. Pada tanaman muda, hal ini dapat menyebabkan “kematian total” pada satu atau beberapa anakan. | | 6 | **Kerusakan pada panen (padi) – anakan berwarna coklat‑kehitaman** | Pada fase generatif, lesi muncul pada anakan (spikelet) dan lembaran anakan. Anakan menjadi coklat, mengering, dan tidak menghasilkan beras yang baik. | | 7 | **Pertumbuhan terhambat / kerdil** | Tanaman yang terinfeksi biasanya lebih pendek, daun lebih sempit, dan pertumbuhan total berkurang 10‑30 % dibandingkan tanaman sehat. | | 8 | **Munculnya miselium putih/berwarna keabu-abuan** | Pada lesi yang sudah tua, terutama pada batang dan anakan, dapat terlihat lapisan miselium berwarna putih atau keabu-abuan yang menandakan fase reproduksi jamur. | | 9 | **Penurunan hasil** | Karena kombinasi kerusakan daun, batang, dan anakan, hasil gabah berkurang secara signifikan (biasanya 15‑40 % pada serangan berat). | ### Ciri‑ciri khusus yang membedakan **Walang Sangit** dari penyakit lain 1. **Lesi berwarna coklat‑kehitaman dengan tepi tidak jelas** – berbeda dengan bercak kuning pada *blast* (Penyakit Bercak Daun). 2. **Keterlibatan sekaligus daun, selubung, batang, dan anakan** – penyakit ini menyerang banyak bagian tanaman secara bersamaan, sehingga disebut “Walang Sangit” (kombinasi “walang” = bercak daun, “sangit” = busuk batang/leher). 3. **Miselium putih/keabu‑abu pada lesi tua** – biasanya tidak terlihat pada *blast* atau *hollow leaf*. ### Kapan gejala biasanya muncul? - **2‑3 minggu setelah tanam** pada lahan yang basah atau setelah hujan lebat. - **Pada fase generatif (pembentukan anakan)**, terutama bila kelembapan tinggi dan suhu berada pada kisaran 25‑30 °C. ### Apa yang harus dilakukan bila gejala terdeteksi? 1. **Identifikasi cepat** – periksa lesi pada daun, selubung, batang, dan anakan. 2. **Pemupukan yang tepat** – beri pupuk nitrogen dengan dosis seimbang (hindari kelebihan N yang memperparah serangan). 3. **Pengendalian kultur** – rotasi tanaman, bersihkan sisa tanaman yang terinfeksi, dan gunakan bibit bersertifikat bebas patogen. 4. **Aplikasi fungisida** – pilih fungisida yang terdaftar efektif melawan *Cochliobolus miyabeanus* (mis. triazol, strobilurin) dan aplikasikan pada fase vegetatif awal serta sebelum pembentukan anakan. 5. **Pengaturan irigasi** – hindari genangan air lama; gunakan sistem irigasi tetes atau aliran yang baik untuk mengurangi kelembapan berlebih. Dengan memperhatikan gejala‑gejala di atas, petani dapat mendeteksi serangan **Walang Sangit** lebih awal dan mengambil langkah‑langkah pengendalian yang tepat sebelum kerusakan meluas. Semoga informasi ini membantu! | G13: 0.75 | H13: 1 | I13: 1 | J13: 0.8445952 | K13: 0.86 | L13: 0.92658639 | M13: 0.96 | N13: Tidak
